<?xml version='1.0'?>

<robot name="robokoko" xmlns:xacro="http://www.ros.org/wiki/xacro">

	<xacro:include filename="$(find robokoko)/urdf/robokoko.gazebo" />

	<gazebo reference="chassis">
  	<material>Gazebo/Black</material>
	</gazebo>

	<gazebo reference="camera">
  	<material>Gazebo/Black</material>
	</gazebo>

	<gazebo reference="left_wheel">
  	<material>Gazebo/Yellow</material>
	</gazebo>

	<gazebo reference="right_wheel">
  	<material>Gazebo/Yellow</material>
	</gazebo>

	<gazebo reference="back_caster">
  	<material>Gazebo/Gray</material>
	</gazebo>

	<material name="yellow">
		<color rgba="1 1 0 1"/>
  </material>  

	<material name="black">
   	<color rgba="0 0 0 1"/>
  </material>    

  <link name="robot_footprint"></link>

	<!-- Chassis  -->

  <joint name="robot_footprint_joint" type="fixed">
    <origin xyz="0 0 0" rpy="0 0 0" />
    <parent link="robot_footprint"/>
    <child link="chassis" />
  </joint>

  <link name='chassis'>
    <pose>0 0 0.1 0 0 0</pose>

    <inertial>
      <mass value="0.5"/>
      <origin xyz="0.0 0 0" rpy=" 0 0 0"/>
      <inertia
          ixx="0.00043333333333333337" ixy="0" ixz="0"
          iyy="0.002033333333333333" iyz="0"
          izz="0.0024333333333333334"
      />
    </inertial>

    <collision name='collision'>
      <origin xyz="0 0 0" rpy=" 0 0 0"/> 
      <geometry>
        <box size="0.22 .10 .02"/>
      </geometry>
    </collision>

    <visual name='chassis_visual'>
      <origin xyz="0 0 0" rpy=" 0 0 0"/>
      <geometry>
        <box size="0.22 .10 .02"/>
      </geometry>
			<material name="black"/>
		</visual>

  </link>

	<!-- Left Wheel  -->

	<joint name="left_wheel_hinge" type="continuous" >
		<parent link="chassis"/>
		<child link="left_wheel"/>
		<axis xyz="0 1 0" rpy="0 0 0">
		</axis>
		<origin xyz="0.03 0.065 0" rpy="0 0 0"/>
    <limit effort="10000" velocity="1000"/>
	</joint>

	<link name='left_wheel'>

		<inertial>
			<mass value="0.1"/>
			<origin xyz="0.0 0 0" rpy="0 1.5707 1.5707"/>
			<inertia
			  ixx="0.000135" ixy="0" ixz="0"
			  iyy="0.000135" iyz="0"
			  izz="9e-05"
			/>
		</inertial>

		<collision name='collision'>
			<origin xyz="0.0 0 0" rpy="0 1.5707 1.5707"/>
			<geometry>
				<cylinder radius="0.03" length="0.03"/>
			</geometry>
		</collision>

		<visual name='left_wheel_visual'>
			<origin xyz="0.0 0 0" rpy="0 1.5707 1.5707"/>
			<geometry>
				<cylinder radius="0.03" length="0.03"/>
				</geometry>
				<material name="yellow"/>
		</visual>

	</link>

	<!-- Right Wheel  -->

	<joint name="right_wheel_hinge" type="continuous" >
		<parent link="chassis"/>
		<child link="right_wheel"/>
		<axis xyz="0 1 0" rpy="0 0 0">
		</axis>
		<origin xyz="0.03 -0.065 0" rpy="0 0 0"/>
		<limit effort="10000" velocity="1000"/>
	</joint>

	<link name='right_wheel'>

		<inertial>
			<mass value="0.1"/>
			<origin xyz="0.0 0 0" rpy="0 1.5707 1.5707"/>
			<inertia
			  ixx="0.000135" ixy="0" ixz="0"
			  iyy="0.000135" iyz="0"
			  izz="9e-05"
			/>
		</inertial>

		<collision name='collision'>
			<origin xyz="0.0 0 0" rpy="0 1.5707 1.5707"/>
			<geometry>
				<cylinder radius="0.03" length="0.03"/>
			</geometry>
		</collision>

		<visual name='right_wheel_visual'>
			<origin xyz="0.0 0 0" rpy="0 1.5707 1.5707"/>
			<geometry>
				<cylinder radius="0.03" length="0.03"/>
			</geometry>
			<material name="yellow"/>
		</visual>

	</link>

	<!-- Back_caster  -->

	<joint name="back_caster_joint" type="fixed" >
		<parent link="chassis"/>
		<child link="back_caster"/>
		<axis xyz="0 1 0" rpy="0 0 0">
		</axis>
    <origin xyz="-0.09 0 -0.01" rpy=" 0 0 0"/>
		<limit effort="10000" velocity="1000"/>
	</joint>

	<link name='back_caster'>

		<inertial>
			<mass value="0.3"/>
			<origin xyz="0.0 0 0" rpy="0 1.5707 1.5707"/>
			<inertia
			  ixx="4.8e-05" ixy="0" ixz="0"
			  iyy="4.8e-05" iyz="0"
			  izz="4.8e-05"/>
		</inertial>

		<collision name='back_caster_collision'>
			<origin xyz="0.0 0 0" rpy="0 1.5707 1.5707"/>
			<geometry>
				<sphere radius="0.02"/>
			</geometry>
		</collision>

		<visual name='back_caster_visual'>
			<origin xyz="0.0 0 0" rpy="0 1.5707 1.5707"/>
			<geometry>
				<sphere radius="0.02"/>
			</geometry>
			<material name="black"/>
		</visual>

	</link>

	<!-- Lidar -->

	<joint name="hokuyo_joint" type="fixed" >
		<parent link="chassis"/>
		<child link="hokuyo"/>
		<origin xyz="0.08 0 0.04" rpy="0 0 0"/>
	</joint>

	<link name='hokuyo'>

		<inertial>
			<mass value="0.1"/>
			<origin xyz="0.0 0 0" rpy="0 0 0"/>
			<inertia
			  ixx="1e-6" ixy="0" ixz="0"
			  iyy="1e-6" iyz="0"
			  izz="1e-6"
			/>
		</inertial>

		<collision name='collision'>
			<origin xyz="0.0 0 0" rpy="0 0 0"/>
			<geometry>
				<box size="0.1 0.1 0.1"/>
			</geometry>
		</collision>

		<visual name='camera_visual'>
			<origin xyz="0.0 0 0" rpy="0 0 0"/>
			<geometry>
				<mesh filename="package://robokoko/meshes/hokuyo.dae"/>	
			</geometry>
		</visual>

	</link>

	<!-- Camera -->

	<joint name="camera_joint" type="fixed" >
		<parent link="chassis"/>
		<child link="camera"/>
		<origin xyz="0.11 0 0" rpy="0 0 0"/>
	</joint>

	<link name='camera'>

		<inertial>
			<mass value="0.1"/>
			<origin xyz="0.0 0 0" rpy="0 0 0"/>
			<inertia
			  ixx="1e-6" ixy="0" ixz="0"
			  iyy="1e-6" iyz="0"
			  izz="1e-6"
			/>
		</inertial>

		<collision name='collision'>
			<origin xyz="0.0 0 0" rpy="0 0 0"/>
			<geometry>
				<box size="0.02 0.1 0.02"/>
			</geometry>
		</collision>

		<visual name='camera_visual'>
			<origin xyz="0.0 0 0" rpy="0 0 0"/>
			<geometry>
				<box size="0.02 0.1 0.02"/>
			</geometry>
			<material name="black"/>
		</visual>

	</link>

</robot>
