<?xml version='1.0'?>

<robot name="robokoko" xmlns:xacro="http://www.ros.org/wiki/xacro">

  <link name="robot_footprint"></link>

  <joint name="robot_footprint_joint" type="fixed">
    <origin xyz="0 0 0" rpy="0 0 0" />
    <parent link="robot_footprint"/>
    <child link="chassis" />
  </joint>

  <link name='chassis'>
    <pose>0 0 0.1 0 0 0</pose>

    <inertial>
      <mass value="0.5"/>
      <origin xyz="0.0 0 0" rpy=" 0 0 0"/>
      <inertia
          ixx="0.1" ixy="0" ixz="0"
          iyy="0.1" iyz="0"
          izz="0.1"
      />
    </inertial>

    <collision name='collision'>
      <origin xyz="0 0 0" rpy=" 0 0 0"/> 
      <geometry>
        <box size="0.22 .10 .02"/>
      </geometry>
    </collision>

    <visual name='chassis_visual'>
      <origin xyz="0 0 0" rpy=" 0 0 0"/>
      <geometry>
        <box size="0.22 .10 .02"/>
      </geometry>
			<material name="blue">
      	<color rgba="0 0 .8 1"/>
      </material>    
		</visual>

  </link>

	<joint name="left_wheel_hinge" type="continuous" >
		<parent link="chassis"/>
		<child link="left_wheel"/>
		<axis xyz="0 1 0" rpy="0 0 0">
		</axis>
		<origin xyz="-0.03 0.065 0" rpy="0 0 0"/>
    <limit effort="10000" velocity="1000"/>
	</joint>


	<link name='left_wheel'>

		<inertial>
			<mass value="0.1"/>
			<origin xyz="0.0 0 0" rpy="0 1.5707 1.5707"/>
			<inertia
			  ixx="0.0135" ixy="0" ixz="0"
			  iyy="0.0135" iyz="0"
			  izz="0.025"
			/>
		</inertial>

		<collision name='collision'>
			<origin xyz="0.0 0 0" rpy="0 1.5707 1.5707"/>
			<geometry>
				<cylinder radius="0.03" length="0.03"/>
			</geometry>
		</collision>

		<visual name='left_wheel_visual'>
			<origin xyz="0.0 0 0" rpy="0 1.5707 1.5707"/>
			<geometry>
				<cylinder radius="0.03" length="0.03"/>
			</geometry>
			<material name="yellow"/>
		</visual>

	</link>

	<joint name="right_wheel_hinge" type="continuous" >
		<parent link="chassis"/>
		<child link="right_wheel"/>
		<axis xyz="0 1 0" rpy="0 0 0">
		</axis>
		<origin xyz="-0.03 -0.065 0" rpy="0 0 0"/>
		<limit effort="10000" velocity="1000"/>
	</joint>

	<link name='right_wheel'>

		<inertial>
			<mass value="0.1"/>
			<origin xyz="0.0 0 0" rpy="0 1.5707 1.5707"/>
			<inertia
			  ixx="0.0135" ixy="0" ixz="0"
			  iyy="0.0135" iyz="0"
			  izz="0.025"
			/>
		</inertial>

		<collision name='collision'>
			<origin xyz="0.0 0 0" rpy="0 1.5707 1.5707"/>
			<geometry>
				<cylinder radius="0.03" length="0.03"/>
			</geometry>
		</collision>

		<visual name='right_wheel_visual'>
			<origin xyz="0.0 0 0" rpy="0 1.5707 1.5707"/>
			<geometry>
				<cylinder radius="0.03" length="0.03"/>
			</geometry>
			<material name="yellow"/>
		</visual>

	</link>

	<joint name="back_caster_joint" type="fixed" >
		<parent link="chassis"/>
		<child link="back_caster"/>
		<axis xyz="0 1 0" rpy="0 0 0">
		</axis>
    <origin xyz="0.09 0 -0.01" rpy=" 0 0 0"/>
		<limit effort="10000" velocity="1000"/>
	</joint>

	<link name='back_caster'>

		<inertial>
			<mass value="0.1"/>
			<origin xyz="0.0 0 0" rpy="0 1.5707 1.5707"/>
			<inertia
			  ixx="0.0135" ixy="0" ixz="0"
			  iyy="0.0135" iyz="0"
			  izz="0.025"/>
		</inertial>

		<collision name='back_caster_collision'>
			<origin xyz="0.0 0 0" rpy="0 1.5707 1.5707"/>
			<geometry>
				<sphere radius="0.02"/>
			</geometry>
		</collision>

		<visual name='back_caster_visual'>
			<origin xyz="0.0 0 0" rpy="0 1.5707 1.5707"/>
			<geometry>
				<sphere radius="0.02"/>
			</geometry>
			<material name="black"/>
		</visual>

	</link>

</robot>
